<?xml version="1.0" ?>
<!-- Generated using onshape-to-robot -->
<!-- Onshape https://cad.onshape.com/documents/ed1b080484db78e51ca91539/w/7397a458a49a8100160f52cd/e/9cc5d95f68bd237afce05dc0 -->
<robot name="robot" xmlns:xacro="http://www.ros.org/wiki/xacro">
<xacro:arg name="sim_mode" default="false"/>

<xacro:if value="$(arg sim_mode)">
  <xacro:include filename="$(find quadro)/description/leg.gazebo" />
</xacro:if>

<xacro:unless value="$(arg sim_mode)">
  <xacro:include filename="$(find quadro)/description/robot_ros2_control.xacro" />
</xacro:unless>
  <!-- Link motor -->
  <link name="world"/>

  <joint name="fixed" type="fixed">
    <parent link="world"/>
    <child link="motor"/>
  </joint>

  <!-- Link motor -->
  <link name="motor">
    <inertial>
      <origin xyz="-0.0236869 0.0333936 0.0493711" rpy="0 0 0"/>
      <mass value="0.586935"/>
      <inertia ixx="0.000559915" ixy="9.50807e-06" ixz="0.000198772" iyy="0.00147041" iyz="-5.98234e-05" izz="0.0015943"/>
    </inertial>
    <!-- Part motor -->
    <visual>
      <origin xyz="-0.055 0.0342754 0.051" rpy="-1.5708 -1.5708 0"/>
      <geometry>
        <mesh filename="file://$(find quadro)/description/leg_assets/motor.stl"/>
      </geometry>
      <material name="motor_material">
        <color rgba="0.498039 0.498039 0.498039 1"/>
      </material>
    </visual>
    <collision>
      <origin xyz="-0.055 0.0342754 0.051" rpy="-1.5708 -1.5708 0"/>
      <geometry>
        <mesh filename="file://$(find quadro)/description/leg_assets/motor.stl"/>
      </geometry>
    </collision>
    <!-- Part back_plate -->
    <visual>
      <origin xyz="-1.38778e-17 0.0692754 0.04" rpy="1.5708 -0 0"/>
      <geometry>
        <mesh filename="file://$(find quadro)/description/leg_assets/back_plate.stl"/>
      </geometry>
      <material name="back_plate_material">
        <color rgba="1 0.756863 0.054902 1"/>
      </material>
    </visual>
    <collision>
      <origin xyz="-1.38778e-17 0.0692754 0.04" rpy="1.5708 -0 0"/>
      <geometry>
        <mesh filename="file://$(find quadro)/description/leg_assets/back_plate.stl"/>
      </geometry>
    </collision>
    <!-- Part back_stop -->
    <visual>
      <origin xyz="2.498e-16 0.0692754 -0.0079" rpy="-1.5708 -0 3.14159"/>
      <geometry>
        <mesh filename="file://$(find quadro)/description/leg_assets/back_stop.stl"/>
      </geometry>
      <material name="back_stop_material">
        <color rgba="1 0.756863 0.054902 1"/>
      </material>
    </visual>
    <collision>
      <origin xyz="2.498e-16 0.0692754 -0.0079" rpy="-1.5708 -0 3.14159"/>
      <geometry>
        <mesh filename="file://$(find quadro)/description/leg_assets/back_stop.stl"/>
      </geometry>
    </collision>
  </link>
  <!-- Link shaft -->
  <link name="shaft">
    <inertial>
      <origin xyz="-0.00365203 -0.00743033 -0.0538481" rpy="0 0 0"/>
      <mass value="0.500834"/>
      <inertia ixx="0.000667976" ixy="4.87254e-05" ixz="-1.74582e-05" iyy="0.000715416" iyz="-3.36343e-05" izz="0.000280763"/>
    </inertial>
    <!-- Part lin_1_support_br -->
    <visual>
      <origin xyz="-0.014 -0.0242487 -0.0735" rpy="2.61799 -1.5708 0"/>
      <geometry>
        <mesh filename="file://$(find quadro)/description/leg_assets/lin_1_support_br.stl"/>
      </geometry>
      <material name="lin_1_support_br_material">
        <color rgba="1 0.756863 0.054902 1"/>
      </material>
    </visual>
    <collision>
      <origin xyz="-0.014 -0.0242487 -0.0735" rpy="2.61799 -1.5708 0"/>
      <geometry>
        <mesh filename="file://$(find quadro)/description/leg_assets/lin_1_support_br.stl"/>
      </geometry>
    </collision>
    <!-- Part shaft -->
    <visual>
      <origin xyz="0 0 0.01" rpy="1.5708 1.5708 0"/>
      <geometry>
        <mesh filename="file://$(find quadro)/description/leg_assets/shaft.stl"/>
      </geometry>
      <material name="shaft_material">
        <color rgba="0.498039 0.498039 0.498039 1"/>
      </material>
    </visual>
    <collision>
      <origin xyz="0 0 0.01" rpy="1.5708 1.5708 0"/>
      <geometry>
        <mesh filename="file://$(find quadro)/description/leg_assets/shaft.stl"/>
      </geometry>
    </collision>
    <!-- Part motor_2 -->
    <visual>
      <origin xyz="-0.0085 -0.0147224 -0.0735" rpy="-1.5708 1.52638e-15 1.0472"/>
      <geometry>
        <mesh filename="file://$(find quadro)/description/leg_assets/motor.stl"/>
      </geometry>
      <material name="motor_2_material">
        <color rgba="0.498039 0.498039 0.498039 1"/>
      </material>
    </visual>
    <collision>
      <origin xyz="-0.0085 -0.0147224 -0.0735" rpy="-1.5708 1.52638e-15 1.0472"/>
      <geometry>
        <mesh filename="file://$(find quadro)/description/leg_assets/motor.stl"/>
      </geometry>
    </collision>
  </link>
  <!-- Link lin_2_br -->
  <link name="lin_2_br">
    <inertial>
      <origin xyz="-0.00583084 -0.0129347 -0.0439786" rpy="0 0 0"/>
      <mass value="0.55866"/>
      <inertia ixx="0.00153356" ixy="-0.000384147" ixz="-0.000112834" iyy="0.000635101" iyz="-0.000224573" izz="0.00157526"/>
    </inertial>
    <!-- Part lin_2_br -->
    <visual>
      <origin xyz="-0.0577297 0.123802 -0.0195" rpy="1.5708 6.50343e-15 2.00713"/>
      <geometry>
        <mesh filename="file://$(find quadro)/description/leg_assets/lin_2_br.stl"/>
      </geometry>
      <material name="lin_2_br_material">
        <color rgba="1 0.756863 0.054902 1"/>
      </material>
    </visual>
    <collision>
      <origin xyz="-0.0577297 0.123802 -0.0195" rpy="1.5708 6.50343e-15 2.00713"/>
      <geometry>
        <mesh filename="file://$(find quadro)/description/leg_assets/lin_2_br.stl"/>
      </geometry>
    </collision>
    <!-- Part shaft_2 -->
    <visual>
      <origin xyz="1.38778e-17 2.77556e-17 0.01" rpy="1.5708 1.5708 0"/>
      <geometry>
        <mesh filename="file://$(find quadro)/description/leg_assets/shaft.stl"/>
      </geometry>
      <material name="shaft_2_material">
        <color rgba="0.498039 0.498039 0.498039 1"/>
      </material>
    </visual>
    <collision>
      <origin xyz="1.38778e-17 2.77556e-17 0.01" rpy="1.5708 1.5708 0"/>
      <geometry>
        <mesh filename="file://$(find quadro)/description/leg_assets/shaft.stl"/>
      </geometry>
    </collision>
    <!-- Part lin_3_top_r -->
    <visual>
      <origin xyz="8.11851e-16 -1.38778e-16 -0.0645" rpy="1.5708 -4.26631e-15 1.22173"/>
      <geometry>
        <mesh filename="file://$(find quadro)/description/leg_assets/lin_3_top_r.stl"/>
      </geometry>
      <material name="lin_3_top_r_material">
        <color rgba="1 0.756863 0.054902 1"/>
      </material>
    </visual>
    <collision>
      <origin xyz="8.11851e-16 -1.38778e-16 -0.0645" rpy="1.5708 -4.26631e-15 1.22173"/>
      <geometry>
        <mesh filename="file://$(find quadro)/description/leg_assets/lin_3_top_r.stl"/>
      </geometry>
    </collision>
    <!-- Part lin_3_bot_r -->
    <visual>
      <origin xyz="8.32667e-16 -2.77556e-17 -0.0645" rpy="1.5708 -4.18305e-15 1.22173"/>
      <geometry>
        <mesh filename="file://$(find quadro)/description/leg_assets/lin_3_bot_r.stl"/>
      </geometry>
      <material name="lin_3_bot_r_material">
        <color rgba="1 0.756863 0.054902 1"/>
      </material>
    </visual>
    <collision>
      <origin xyz="8.32667e-16 -2.77556e-17 -0.0645" rpy="1.5708 -4.18305e-15 1.22173"/>
      <geometry>
        <mesh filename="file://$(find quadro)/description/leg_assets/lin_3_bot_r.stl"/>
      </geometry>
    </collision>
    <!-- Part motor_3 -->
    <visual>
      <origin xyz="8.39606e-16 -5.55112e-17 -0.0385" rpy="2.70526 1.5708 0"/>
      <geometry>
        <mesh filename="file://$(find quadro)/description/leg_assets/motor.stl"/>
      </geometry>
      <material name="motor_3_material">
        <color rgba="0.498039 0.498039 0.498039 1"/>
      </material>
    </visual>
    <collision>
      <origin xyz="8.39606e-16 -5.55112e-17 -0.0385" rpy="2.70526 1.5708 0"/>
      <geometry>
        <mesh filename="file://$(find quadro)/description/leg_assets/motor.stl"/>
      </geometry>
    </collision>
    <!-- Part bearing -->
    <visual>
      <origin xyz="-0.068404 -0.187939 -0.074" rpy="3.14159 -1.23311e-14 0.436332"/>
      <geometry>
        <mesh filename="file://$(find quadro)/description/leg_assets/bearing.stl"/>
      </geometry>
      <material name="bearing_material">
        <color rgba="0.615686 0.811765 0.929412 1"/>
      </material>
    </visual>
    <collision>
      <origin xyz="-0.068404 -0.187939 -0.074" rpy="3.14159 -1.23311e-14 0.436332"/>
      <geometry>
        <mesh filename="file://$(find quadro)/description/leg_assets/bearing.stl"/>
      </geometry>
    </collision>
  </link>
  <!-- Link lin_top_r -->
  <link name="lin_top_r">
    <inertial>
      <origin xyz="0.000209323 -0.00444903 -0.0125923" rpy="0 0 0"/>
      <mass value="0.140118"/>
      <inertia ixx="4.45628e-05" ixy="6.46821e-07" ixz="3.78582e-07" iyy="1.92125e-05" iyz="-8.04655e-06" izz="4.62705e-05"/>
    </inertial>
    <!-- Part lin_top_r -->
    <visual>
      <origin xyz="-2.77556e-17 -2.77556e-17 0.003" rpy="1.5708 1.99014e-16 0"/>
      <geometry>
        <mesh filename="file://$(find quadro)/description/leg_assets/lin_top_r.stl"/>
      </geometry>
      <material name="lin_top_r_material">
        <color rgba="1 0.756863 0.054902 1"/>
      </material>
    </visual>
    <collision>
      <origin xyz="-2.77556e-17 -2.77556e-17 0.003" rpy="1.5708 1.99014e-16 0"/>
      <geometry>
        <mesh filename="file://$(find quadro)/description/leg_assets/lin_top_r.stl"/>
      </geometry>
    </collision>
    <!-- Part bearing_2 -->
    <visual>
      <origin xyz="-4.16334e-17 -0.05 -0.0255" rpy="3.14159 8.79922e-17 -1.66533e-16"/>
      <geometry>
        <mesh filename="file://$(find quadro)/description/leg_assets/bearing.stl"/>
      </geometry>
      <material name="bearing_2_material">
        <color rgba="0.615686 0.811765 0.929412 1"/>
      </material>
    </visual>
    <collision>
      <origin xyz="-4.16334e-17 -0.05 -0.0255" rpy="3.14159 8.79922e-17 -1.66533e-16"/>
      <geometry>
        <mesh filename="file://$(find quadro)/description/leg_assets/bearing.stl"/>
      </geometry>
    </collision>
    <!-- Part shaft_3 -->
    <visual>
      <origin xyz="-1.38778e-17 -1.38778e-17 0.01" rpy="1.5708 1.5708 0"/>
      <geometry>
        <mesh filename="file://$(find quadro)/description/leg_assets/shaft.stl"/>
      </geometry>
      <material name="shaft_3_material">
        <color rgba="0.498039 0.498039 0.498039 1"/>
      </material>
    </visual>
    <collision>
      <origin xyz="-1.38778e-17 -1.38778e-17 0.01" rpy="1.5708 1.5708 0"/>
      <geometry>
        <mesh filename="file://$(find quadro)/description/leg_assets/shaft.stl"/>
      </geometry>
    </collision>
  </link>
  <!-- Joint from lin_2_br to lin_top_r -->
  <joint name="joint_br_3" type="revolute">
    <origin xyz="8.46545e-16 -2.77556e-17 -0.0485" rpy="-5.42096e-15 -1.33858e-14 0.436332"/>
    <parent link="lin_2_br"/>
    <child link="lin_top_r"/>
    <axis xyz="0 0 -1"/>
    <limit effort="10" velocity="12" lower="-3.14" upper="3.14"/>
    <joint_properties friction="0.5"/>
  </joint>
  <!-- Link lin_4_r -->
  <link name="lin_4_r">
    <inertial>
      <origin xyz="-0.00037679 -0.0270176 -5.21118e-10" rpy="0 0 0"/>
      <mass value="0.0488058"/>
      <inertia ixx="0.000183398" ixy="1.69668e-06" ixz="2.68516e-13" iyy="4.65047e-06" iyz="1.73007e-12" izz="0.00018765"/>
    </inertial>
    <!-- Part lin_4_r -->
    <visual>
      <origin xyz="0.2 -6.91114e-15 -0.0085" rpy="-1.5708 -1.96624e-17 -3.4972e-14"/>
      <geometry>
        <mesh filename="file://$(find quadro)/description/leg_assets/lin_4_r.stl"/>
      </geometry>
      <material name="lin_4_r_material">
        <color rgba="1 0.756863 0.054902 1"/>
      </material>
    </visual>
    <collision>
      <origin xyz="0.2 -6.91114e-15 -0.0085" rpy="-1.5708 -1.96624e-17 -3.4972e-14"/>
      <geometry>
        <mesh filename="file://$(find quadro)/description/leg_assets/lin_4_r.stl"/>
      </geometry>
    </collision>
    <!-- Part bearing_3 -->
    <visual>
      <origin xyz="1.72085e-15 0.05 -1.38778e-17" rpy="3.14159 -1.96624e-17 -3.49165e-14"/>
      <geometry>
        <mesh filename="file://$(find quadro)/description/leg_assets/bearing.stl"/>
      </geometry>
      <material name="bearing_3_material">
        <color rgba="0.615686 0.811765 0.929412 1"/>
      </material>
    </visual>
    <collision>
      <origin xyz="1.72085e-15 0.05 -1.38778e-17" rpy="3.14159 -1.96624e-17 -3.49165e-14"/>
      <geometry>
        <mesh filename="file://$(find quadro)/description/leg_assets/bearing.stl"/>
      </geometry>
    </collision>
  </link>
  <!-- Joint from lin_2_br to lin_4_r -->
  <joint name="l4_l3" type="revolute">
    <origin xyz="-0.068404 -0.187939 -0.074" rpy="3.14159 -1.23311e-14 0.436332"/>
    <parent link="lin_2_br"/>
    <child link="lin_4_r"/>
    <axis xyz="0 0 -1"/>
    <limit effort="10" velocity="12" lower="-3.14" upper="3.14"/>
    <joint_properties friction="0.5"/>
    <mimic joint="joint_br_3" multiplier="-1.0"/>
  </joint>
  <!-- Joint from shaft to lin_2_br -->
  <joint name="joint_br_2" type="revolute">
    <origin xyz="-0.0035 -0.00606218 -0.0735" rpy="1.5708 -0.0310412 -0.523599"/>
    <parent link="shaft"/>
    <child link="lin_2_br"/>
    <axis xyz="0 0 -1"/>
    <limit effort="10" velocity="12" lower="-3.14" upper="3.14"/>
    <joint_properties friction="0.5"/>
  </joint>
  <!-- Joint from motor to shaft -->
  <joint name="joint_br_1" type="revolute">
    <origin xyz="-0.055 0.0342754 0.061" rpy="-3.14159 -2.04333e-29 -1.5708"/>
    <parent link="motor"/>
    <child link="shaft"/>
    <axis xyz="0 0 -1"/>
    <limit effort="10" velocity="12" lower="-3.14" upper="3.14"/>
    <joint_properties friction="0.5"/>
  </joint>
</robot>
