<?xml version="1.0" ?>
<!-- Generated using onshape-to-robot -->
<!-- Onshape https://cad.onshape.com/documents/bab46d1a02d1cb675f27d5f3/w/8adfe612a59991dc5461d3ee/e/fd595c6fbcbfabdca437c483 -->
<robot name="leg" xmlns:xacro="http://www.ros.org/wiki/xacro">
<xacro:arg name="sim_mode" default="true"/>

<xacro:if value="$(arg sim_mode)">
  <xacro:include filename="$(find quadro)/description/leg.gazebo" />
</xacro:if>

  <link name="world"/>

  <joint name="fixed" type="fixed">
    <parent link="world"/>
    <child link="motor"/>
  </joint>

  <!-- Link shaft -->
  <link name="shaft">
    <inertial>
      <origin xyz="-0.00100224 0.00617513 0.0818763" rpy="0 0 0"/>
      <mass value="0.453012"/>
      <inertia ixx="0.000489604" ixy="-7.28122e-06" ixz="1.56037e-06" iyy="0.000609097" iyz="-1.64399e-05" izz="0.000239462"/>
    </inertial>
    <!-- Part shaft -->
    <visual>
      <origin xyz="-8.07509e-16 -4.69306e-16 0.011" rpy="0.872665 -1.5708 0"/>
      <geometry>
        <mesh filename="file://$(find quadro)/description/leg_assets/shaft.stl"/>
      </geometry>
      <material name="shaft_material">
        <color rgba="0.498039 0.498039 0.498039 1"/>
      </material>
    </visual>
    <collision>
      <origin xyz="-8.07509e-16 -4.69306e-16 0.011" rpy="0.872665 -1.5708 0"/>
      <geometry>
        <mesh filename="file://$(find quadro)/description/leg_assets/shaft.stl"/>
      </geometry>
    </collision>
    <!-- Part motor -->
    <visual>
      <origin xyz="-0.00148165 0.0169353 0.0945" rpy="-1.5708 8.89644e-15 -1.48353"/>
      <geometry>
        <mesh filename="file://$(find quadro)/description/leg_assets/motor.stl"/>
      </geometry>
      <material name="motor_material">
        <color rgba="0.498039 0.498039 0.498039 1"/>
      </material>
    </visual>
    <collision>
      <origin xyz="-0.00148165 0.0169353 0.0945" rpy="-1.5708 8.89644e-15 -1.48353"/>
      <geometry>
        <mesh filename="file://$(find quadro)/description/leg_assets/motor.stl"/>
      </geometry>
    </collision>
    <!-- Part lin_1_support_bl -->
    <visual>
      <origin xyz="-0.00845411 0.0966309 0.0945" rpy="3.05433 1.5708 0"/>
      <geometry>
        <mesh filename="file://$(find quadro)/description/leg_assets/lin_1_support_bl.stl"/>
      </geometry>
      <material name="lin_1_support_bl_material">
        <color rgba="0.901961 0.901961 0.901961 1"/>
      </material>
    </visual>
    <collision>
      <origin xyz="-0.00845411 0.0966309 0.0945" rpy="3.05433 1.5708 0"/>
      <geometry>
        <mesh filename="file://$(find quadro)/description/leg_assets/lin_1_support_bl.stl"/>
      </geometry>
    </collision>
  </link>
  <!-- Link motor -->
  <link name="motor">
    <inertial>
      <origin xyz="-0.00034083 -2.5357e-05 0.00266737" rpy="0 0 0"/>
      <mass value="0.319783"/>
      <inertia ixx="0.00016651" ixy="-2.01865e-06" ixz="-8.2078e-07" iyy="0.000167286" iyz="9.47527e-07" izz="0.000282579"/>
    </inertial>
    <!-- Part motor_2 -->
    <visual>
      <origin xyz="-6.78949e-19 8.0914e-19 -0.01" rpy="2.26893 -1.5708 0"/>
      <geometry>
        <mesh filename="file://$(find quadro)/description/leg_assets/motor.stl"/>
      </geometry>
      <material name="motor_2_material">
        <color rgba="0.498039 0.498039 0.498039 1"/>
      </material>
    </visual>
    <collision>
      <origin xyz="-6.78949e-19 8.0914e-19 -0.01" rpy="2.26893 -1.5708 0"/>
      <geometry>
        <mesh filename="file://$(find quadro)/description/leg_assets/motor.stl"/>
      </geometry>
    </collision>
  </link>
  <!-- Joint from motor to shaft -->
  <joint name="bl_m1_s1" type="revolute">
    <origin xyz="-7.16465e-16 -4.82211e-16 -0.025" rpy="4.96925e-15 -7.80392e-15 2.44346"/>
    <parent link="motor"/>
    <child link="shaft"/>
    <axis xyz="0 0 1"/>
    <limit effort="10" velocity="12" lower="-3.14" upper="3.14"/>
    <joint_properties friction="0.5"/>
  </joint>
  <!-- Link shaft_2 -->
  <link name="shaft_2">
    <inertial>
      <origin xyz="0.00679431 0.00633758 -0.0491985" rpy="0 0 0"/>
      <mass value="0.524841"/>
      <inertia ixx="0.000610231" ixy="-0.000236595" ixz="0.000101861" iyy="0.000743295" iyz="0.00010283" izz="0.000885096"/>
    </inertial>
    <!-- Part lin_2_bl -->
    <visual>
      <origin xyz="-1.38778e-17 6.93889e-18 -0.0195" rpy="1.5708 -9.2554e-16 -0.174533"/>
      <geometry>
        <mesh filename="file://$(find quadro)/description/leg_assets/lin_2_bl.stl"/>
      </geometry>
      <material name="lin_2_bl_material">
        <color rgba="0.901961 0.901961 0.901961 1"/>
      </material>
    </visual>
    <collision>
      <origin xyz="-1.38778e-17 6.93889e-18 -0.0195" rpy="1.5708 -9.2554e-16 -0.174533"/>
      <geometry>
        <mesh filename="file://$(find quadro)/description/leg_assets/lin_2_bl.stl"/>
      </geometry>
    </collision>
    <!-- Part top_l -->
    <visual>
      <origin xyz="2.77556e-17 -3.46945e-17 -0.0725" rpy="1.5708 -1.18469e-15 0.610865"/>
      <geometry>
        <mesh filename="file://$(find quadro)/description/leg_assets/top_l.stl"/>
      </geometry>
      <material name="top_l_material">
        <color rgba="0.901961 0.901961 0.901961 1"/>
      </material>
    </visual>
    <collision>
      <origin xyz="2.77556e-17 -3.46945e-17 -0.0725" rpy="1.5708 -1.18469e-15 0.610865"/>
      <geometry>
        <mesh filename="file://$(find quadro)/description/leg_assets/top_l.stl"/>
      </geometry>
    </collision>
    <!-- Part motor_3 -->
    <visual>
      <origin xyz="0 -1.38778e-17 -0.0395" rpy="-1.39626 1.5708 0"/>
      <geometry>
        <mesh filename="file://$(find quadro)/description/leg_assets/motor.stl"/>
      </geometry>
      <material name="motor_3_material">
        <color rgba="0.498039 0.498039 0.498039 1"/>
      </material>
    </visual>
    <collision>
      <origin xyz="0 -1.38778e-17 -0.0395" rpy="-1.39626 1.5708 0"/>
      <geometry>
        <mesh filename="file://$(find quadro)/description/leg_assets/motor.stl"/>
      </geometry>
    </collision>
    <!-- Part bot_l -->
    <visual>
      <origin xyz="4.16334e-17 -2.77556e-17 -0.0725" rpy="1.5708 -1.18469e-15 0.610865"/>
      <geometry>
        <mesh filename="file://$(find quadro)/description/leg_assets/bot_l.stl"/>
      </geometry>
      <material name="bot_l_material">
        <color rgba="0.901961 0.901961 0.901961 1"/>
      </material>
    </visual>
    <collision>
      <origin xyz="4.16334e-17 -2.77556e-17 -0.0725" rpy="1.5708 -1.18469e-15 0.610865"/>
      <geometry>
        <mesh filename="file://$(find quadro)/description/leg_assets/bot_l.stl"/>
      </geometry>
    </collision>
    <!-- Part shaft_2 -->
    <visual>
      <origin xyz="-1.38778e-17 0 0.01" rpy="1.5708 1.5708 0"/>
      <geometry>
        <mesh filename="file://$(find quadro)/description/leg_assets/shaft.stl"/>
      </geometry>
      <material name="shaft_2_material">
        <color rgba="0.498039 0.498039 0.498039 1"/>
      </material>
    </visual>
    <collision>
      <origin xyz="-1.38778e-17 0 0.01" rpy="1.5708 1.5708 0"/>
      <geometry>
        <mesh filename="file://$(find quadro)/description/leg_assets/shaft.stl"/>
      </geometry>
    </collision>
  </link>
  <!-- Link shaft_3 -->
  <link name="shaft_3">
    <inertial>
      <origin xyz="-0.00823991 0.00823991 -0.0152617" rpy="0 0 0"/>
      <mass value="0.0992632"/>
      <inertia ixx="3.95043e-05" ixy="2.3154e-05" ixz="-1.04189e-05" iyy="3.95043e-05" iyz="1.04189e-05" izz="6.07656e-05"/>
    </inertial>
    <!-- Part bearing -->
    <visual>
      <origin xyz="-0.0388909 0.0388909 -0.032" rpy="-1.5708 -7.72957e-17 -2.35619"/>
      <geometry>
        <mesh filename="file://$(find quadro)/description/leg_assets/bearing.stl"/>
      </geometry>
      <material name="bearing_material">
        <color rgba="0.439216 0.47451 0.501961 1"/>
      </material>
    </visual>
    <collision>
      <origin xyz="-0.0388909 0.0388909 -0.032" rpy="-1.5708 -7.72957e-17 -2.35619"/>
      <geometry>
        <mesh filename="file://$(find quadro)/description/leg_assets/bearing.stl"/>
      </geometry>
    </collision>
    <!-- Part shaft_3 -->
    <visual>
      <origin xyz="1.38778e-17 -3.46945e-18 0.01" rpy="1.5708 1.5708 0"/>
      <geometry>
        <mesh filename="file://$(find quadro)/description/leg_assets/shaft.stl"/>
      </geometry>
      <material name="shaft_3_material">
        <color rgba="0.498039 0.498039 0.498039 1"/>
      </material>
    </visual>
    <collision>
      <origin xyz="1.38778e-17 -3.46945e-18 0.01" rpy="1.5708 1.5708 0"/>
      <geometry>
        <mesh filename="file://$(find quadro)/description/leg_assets/shaft.stl"/>
      </geometry>
    </collision>
    <!-- Part mid_l -->
    <visual>
      <origin xyz="1.38778e-17 0 -0.014" rpy="1.5708 -7.72957e-17 -2.35619"/>
      <geometry>
        <mesh filename="file://$(find quadro)/description/leg_assets/mid_l.stl"/>
      </geometry>
      <material name="mid_l_material">
        <color rgba="0.901961 0.901961 0.901961 1"/>
      </material>
    </visual>
    <collision>
      <origin xyz="1.38778e-17 0 -0.014" rpy="1.5708 -7.72957e-17 -2.35619"/>
      <geometry>
        <mesh filename="file://$(find quadro)/description/leg_assets/mid_l.stl"/>
      </geometry>
    </collision>
  </link>
  <!-- Joint from shaft_2 to shaft_3 -->
  <joint name="bl_m3_s3" type="revolute">
    <origin xyz="0 -2.77556e-17 -0.0495" rpy="1.50009e-15 8.62308e-16 -2.3911"/>
    <parent link="shaft_2"/>
    <child link="shaft_3"/>
    <axis xyz="0 0 1"/>
    <limit effort="10" velocity="12" lower="-3.14" upper="3.14"/>
    <joint_properties friction="0.5"/>
    <mimic joint="bl_l4_l3" multiplier="1.0"/>
  </joint>
  <!-- Link l4_l -->
  <link name="l4_l">
    <inertial>
      <origin xyz="0.000904018 0.036899 -0.00535524" rpy="0 0 0"/>
      <mass value="0.0940232"/>
      <inertia ixx="0.000523053" ixy="1.96238e-06" ixz="4.23975e-07" iyy="8.81622e-06" iyz="3.90493e-06" izz="0.000528442"/>
    </inertial>
    <!-- Part bearing_2 -->
    <visual>
      <origin xyz="-2.77556e-17 8.32667e-17 -0.008" rpy="-1.5708 -8.83135e-18 0"/>
      <geometry>
        <mesh filename="file://$(find quadro)/description/leg_assets/bearing.stl"/>
      </geometry>
      <material name="bearing_2_material">
        <color rgba="0.439216 0.47451 0.501961 1"/>
      </material>
    </visual>
    <collision>
      <origin xyz="-2.77556e-17 8.32667e-17 -0.008" rpy="-1.5708 -8.83135e-18 0"/>
      <geometry>
        <mesh filename="file://$(find quadro)/description/leg_assets/bearing.stl"/>
      </geometry>
    </collision>
    <!-- Part bearing_3 -->
    <visual>
      <origin xyz="-5.55112e-17 -0.055 -0.008" rpy="-1.5708 -8.83135e-18 0"/>
      <geometry>
        <mesh filename="file://$(find quadro)/description/leg_assets/bearing.stl"/>
      </geometry>
      <material name="bearing_3_material">
        <color rgba="0.439216 0.47451 0.501961 1"/>
      </material>
    </visual>
    <collision>
      <origin xyz="-5.55112e-17 -0.055 -0.008" rpy="-1.5708 -8.83135e-18 0"/>
      <geometry>
        <mesh filename="file://$(find quadro)/description/leg_assets/bearing.stl"/>
      </geometry>
    </collision>
    <!-- Part feet -->
    <visual>
      <origin xyz="-0.200014 -0.04 -0.039" rpy="-1.5708 3.00265e-16 -3.14159"/>
      <geometry>
        <mesh filename="file://$(find quadro)/description/leg_assets/feet.stl"/>
      </geometry>
      <material name="feet_material">
        <color rgba="0.917647 0.917647 0.917647 1"/>
      </material>
    </visual>
    <collision>
      <origin xyz="-0.200014 -0.04 -0.039" rpy="-1.5708 3.00265e-16 -3.14159"/>
      <geometry>
        <mesh filename="file://$(find quadro)/description/leg_assets/feet.stl"/>
      </geometry>
    </collision>
    <!-- Part l4_l -->
    <visual>
      <origin xyz="-0.16 -0.002 -0.008" rpy="1.5708 -8.83135e-18 0"/>
      <geometry>
        <mesh filename="file://$(find quadro)/description/leg_assets/l4_l.stl"/>
      </geometry>
      <material name="l4_l_material">
        <color rgba="0.901961 0.901961 0.901961 1"/>
      </material>
    </visual>
    <collision>
      <origin xyz="-0.16 -0.002 -0.008" rpy="1.5708 -8.83135e-18 0"/>
      <geometry>
        <mesh filename="file://$(find quadro)/description/leg_assets/l4_l.stl"/>
      </geometry>
    </collision>
  </link>
  <!-- Joint from shaft_2 to l4_l -->
  <joint name="bl_l4_l3" type="revolute">
    <origin xyz="0.129917 0.0934105 -0.0735" rpy="-1.39777e-15 4.10207e-16 1.53589"/>
    <parent link="shaft_2"/>
    <child link="l4_l"/>
    <axis xyz="0 0 1"/>
    <limit effort="10" velocity="12" lower="-3.14" upper="3.14"/>
    <joint_properties friction="0.5"/>
  </joint>
  <!-- Joint from shaft to shaft_2 -->
  <joint name="bl_m2_s2" type="revolute">
    <origin xyz="-0.00061009 0.00697336 0.0945" rpy="1.5708 -1.0472 -3.05433"/>
    <parent link="shaft"/>
    <child link="shaft_2"/>
    <axis xyz="0 0 1"/>
    <limit effort="10" velocity="12" lower="-3.14" upper="3.14"/>
    <joint_properties friction="0.5"/>
  </joint>
</robot>
