<?xml version="1.0" ?>
<!-- Generated using onshape-to-robot -->
<!-- Onshape https://cad.onshape.com/documents/ed1b080484db78e51ca91539/w/7397a458a49a8100160f52cd/e/9cc5d95f68bd237afce05dc0 -->
<robot name="robot" xmlns:xacro="http://www.ros.org/wiki/xacro">
<xacro:arg name="sim_mode" default="false"/>

<xacro:if value="$(arg sim_mode)">
  <xacro:include filename="$(find quadro)/description/leg.gazebo" />
</xacro:if>

<xacro:unless value="$(arg sim_mode)">
  <xacro:include filename="$(find quadro)/description/robot_ros2_control.xacro" />
</xacro:unless>
  <!-- Link motor -->
  <link name="world"/>

  <joint name="fixed" type="fixed">
    <parent link="world"/>
    <child link="motor"/>
  </joint>

  <!-- Link motor -->
  <link name="motor">
    <inertial>
      <origin xyz="0.000167595 0.0335997 0.0536899" rpy="0 0 0"/>
      <mass value="0.840992"/>
      <inertia ixx="0.000727199" ixy="-1.7348e-08" ixz="-1.37499e-06" iyy="0.00274647" iyz="-6.25483e-05" izz="0.00292446"/>
    </inertial>
    <!-- Part motor -->
    <visual>
      <origin xyz="-0.055 0.0342754 0.051" rpy="-1.5708 -1.5708 0"/>
      <geometry>
        <mesh filename="file://$(find quadro)/description/leg_assets/motor.stl"/>
      </geometry>
      <material name="motor_material">
        <color rgba="0.498039 0.498039 0.498039 1"/>
      </material>
    </visual>
    <collision>
      <origin xyz="-0.055 0.0342754 0.051" rpy="-1.5708 -1.5708 0"/>
      <geometry>
        <mesh filename="file://$(find quadro)/description/leg_assets/motor.stl"/>
      </geometry>
    </collision>
    <!-- Part back_plate -->
    <visual>
      <origin xyz="-1.38778e-17 0.0692754 0.04" rpy="1.5708 -0 0"/>
      <geometry>
        <mesh filename="file://$(find quadro)/description/leg_assets/back_plate.stl"/>
      </geometry>
      <material name="back_plate_material">
        <color rgba="1 0.756863 0.054902 1"/>
      </material>
    </visual>
    <collision>
      <origin xyz="-1.38778e-17 0.0692754 0.04" rpy="1.5708 -0 0"/>
      <geometry>
        <mesh filename="file://$(find quadro)/description/leg_assets/back_plate.stl"/>
      </geometry>
    </collision>
    <!-- Part back_stop -->
    <visual>
      <origin xyz="2.498e-16 0.0692754 -0.0079" rpy="-1.5708 -0 3.14159"/>
      <geometry>
        <mesh filename="file://$(find quadro)/description/leg_assets/back_stop.stl"/>
      </geometry>
      <material name="back_stop_material">
        <color rgba="1 0.756863 0.054902 1"/>
      </material>
    </visual>
    <collision>
      <origin xyz="2.498e-16 0.0692754 -0.0079" rpy="-1.5708 -0 3.14159"/>
      <geometry>
        <mesh filename="file://$(find quadro)/description/leg_assets/back_stop.stl"/>
      </geometry>
    </collision>
    <!-- Part motor_2 -->
    <visual>
      <origin xyz="0.055 0.0342754 0.051" rpy="-1.5708 -1.5708 0"/>
      <geometry>
        <mesh filename="file://$(find quadro)/description/leg_assets/motor.stl"/>
      </geometry>
      <material name="motor_2_material">
        <color rgba="0.498039 0.498039 0.498039 1"/>
      </material>
    </visual>
    <collision>
      <origin xyz="0.055 0.0342754 0.051" rpy="-1.5708 -1.5708 0"/>
      <geometry>
        <mesh filename="file://$(find quadro)/description/leg_assets/motor.stl"/>
      </geometry>
    </collision>
  </link>
  <!-- Link shaft -->
  <link name="shaft">
    <inertial>
      <origin xyz="-0.00365203 -0.00743033 -0.0538481" rpy="0 0 0"/>
      <mass value="0.500834"/>
      <inertia ixx="0.000667976" ixy="4.87254e-05" ixz="-1.74582e-05" iyy="0.000715416" iyz="-3.36343e-05" izz="0.000280763"/>
    </inertial>
    <!-- Part lin_1_support_br -->
    <visual>
      <origin xyz="-0.014 -0.0242487 -0.0735" rpy="2.61799 -1.5708 0"/>
      <geometry>
        <mesh filename="file://$(find quadro)/description/leg_assets/lin_1_support_br.stl"/>
      </geometry>
      <material name="lin_1_support_br_material">
        <color rgba="1 0.756863 0.054902 1"/>
      </material>
    </visual>
    <collision>
      <origin xyz="-0.014 -0.0242487 -0.0735" rpy="2.61799 -1.5708 0"/>
      <geometry>
        <mesh filename="file://$(find quadro)/description/leg_assets/lin_1_support_br.stl"/>
      </geometry>
    </collision>
    <!-- Part shaft -->
    <visual>
      <origin xyz="0 0 0.01" rpy="1.5708 1.5708 0"/>
      <geometry>
        <mesh filename="file://$(find quadro)/description/leg_assets/shaft.stl"/>
      </geometry>
      <material name="shaft_material">
        <color rgba="0.498039 0.498039 0.498039 1"/>
      </material>
    </visual>
    <collision>
      <origin xyz="0 0 0.01" rpy="1.5708 1.5708 0"/>
      <geometry>
        <mesh filename="file://$(find quadro)/description/leg_assets/shaft.stl"/>
      </geometry>
    </collision>
    <!-- Part motor_3 -->
    <visual>
      <origin xyz="-0.0085 -0.0147224 -0.0735" rpy="-1.5708 1.52638e-15 1.0472"/>
      <geometry>
        <mesh filename="file://$(find quadro)/description/leg_assets/motor.stl"/>
      </geometry>
      <material name="motor_3_material">
        <color rgba="0.498039 0.498039 0.498039 1"/>
      </material>
    </visual>
    <collision>
      <origin xyz="-0.0085 -0.0147224 -0.0735" rpy="-1.5708 1.52638e-15 1.0472"/>
      <geometry>
        <mesh filename="file://$(find quadro)/description/leg_assets/motor.stl"/>
      </geometry>
    </collision>
  </link>
  <!-- Link lin_2_br -->
  <link name="lin_2_br">
    <inertial>
      <origin xyz="-0.00583084 -0.0129347 -0.0439786" rpy="0 0 0"/>
      <mass value="0.55866"/>
      <inertia ixx="0.00153356" ixy="-0.000384147" ixz="-0.000112834" iyy="0.000635101" iyz="-0.000224573" izz="0.00157526"/>
    </inertial>
    <!-- Part lin_2_br -->
    <visual>
      <origin xyz="-0.0577297 0.123802 -0.0195" rpy="1.5708 1.94085e-14 2.00713"/>
      <geometry>
        <mesh filename="file://$(find quadro)/description/leg_assets/lin_2_br.stl"/>
      </geometry>
      <material name="lin_2_br_material">
        <color rgba="1 0.756863 0.054902 1"/>
      </material>
    </visual>
    <collision>
      <origin xyz="-0.0577297 0.123802 -0.0195" rpy="1.5708 1.94085e-14 2.00713"/>
      <geometry>
        <mesh filename="file://$(find quadro)/description/leg_assets/lin_2_br.stl"/>
      </geometry>
    </collision>
    <!-- Part shaft_2 -->
    <visual>
      <origin xyz="1.38778e-17 0 0.01" rpy="1.5708 1.5708 0"/>
      <geometry>
        <mesh filename="file://$(find quadro)/description/leg_assets/shaft.stl"/>
      </geometry>
      <material name="shaft_2_material">
        <color rgba="0.498039 0.498039 0.498039 1"/>
      </material>
    </visual>
    <collision>
      <origin xyz="1.38778e-17 0 0.01" rpy="1.5708 1.5708 0"/>
      <geometry>
        <mesh filename="file://$(find quadro)/description/leg_assets/shaft.stl"/>
      </geometry>
    </collision>
    <!-- Part lin_3_top_r -->
    <visual>
      <origin xyz="7.91034e-16 -1.11022e-16 -0.0645" rpy="1.5708 -1.25557e-14 1.22173"/>
      <geometry>
        <mesh filename="file://$(find quadro)/description/leg_assets/lin_3_top_r.stl"/>
      </geometry>
      <material name="lin_3_top_r_material">
        <color rgba="1 0.756863 0.054902 1"/>
      </material>
    </visual>
    <collision>
      <origin xyz="7.91034e-16 -1.11022e-16 -0.0645" rpy="1.5708 -1.25557e-14 1.22173"/>
      <geometry>
        <mesh filename="file://$(find quadro)/description/leg_assets/lin_3_top_r.stl"/>
      </geometry>
    </collision>
    <!-- Part lin_3_bot_r -->
    <visual>
      <origin xyz="8.18789e-16 0 -0.0645" rpy="1.5708 -1.25835e-14 1.22173"/>
      <geometry>
        <mesh filename="file://$(find quadro)/description/leg_assets/lin_3_bot_r.stl"/>
      </geometry>
      <material name="lin_3_bot_r_material">
        <color rgba="1 0.756863 0.054902 1"/>
      </material>
    </visual>
    <collision>
      <origin xyz="8.18789e-16 0 -0.0645" rpy="1.5708 -1.25835e-14 1.22173"/>
      <geometry>
        <mesh filename="file://$(find quadro)/description/leg_assets/lin_3_bot_r.stl"/>
      </geometry>
    </collision>
    <!-- Part motor_4 -->
    <visual>
      <origin xyz="8.25728e-16 -2.77556e-17 -0.0385" rpy="2.70526 1.5708 0"/>
      <geometry>
        <mesh filename="file://$(find quadro)/description/leg_assets/motor.stl"/>
      </geometry>
      <material name="motor_4_material">
        <color rgba="0.498039 0.498039 0.498039 1"/>
      </material>
    </visual>
    <collision>
      <origin xyz="8.25728e-16 -2.77556e-17 -0.0385" rpy="2.70526 1.5708 0"/>
      <geometry>
        <mesh filename="file://$(find quadro)/description/leg_assets/motor.stl"/>
      </geometry>
    </collision>
    <!-- Part bearing -->
    <visual>
      <origin xyz="-0.068404 -0.187939 -0.074" rpy="3.14159 -3.7582e-14 0.436332"/>
      <geometry>
        <mesh filename="file://$(find quadro)/description/leg_assets/bearing.stl"/>
      </geometry>
      <material name="bearing_material">
        <color rgba="0.615686 0.811765 0.929412 1"/>
      </material>
    </visual>
    <collision>
      <origin xyz="-0.068404 -0.187939 -0.074" rpy="3.14159 -3.7582e-14 0.436332"/>
      <geometry>
        <mesh filename="file://$(find quadro)/description/leg_assets/bearing.stl"/>
      </geometry>
    </collision>
  </link>
  <!-- Link lin_top_r -->
  <link name="lin_top_r">
    <inertial>
      <origin xyz="0.000209323 -0.00444903 -0.0125923" rpy="0 0 0"/>
      <mass value="0.140118"/>
      <inertia ixx="4.45628e-05" ixy="6.46821e-07" ixz="3.78582e-07" iyy="1.92125e-05" iyz="-8.04655e-06" izz="4.62705e-05"/>
    </inertial>
    <!-- Part lin_top_r -->
    <visual>
      <origin xyz="-2.77556e-17 4.16334e-17 0.003" rpy="1.5708 -7.50078e-16 5.55112e-17"/>
      <geometry>
        <mesh filename="file://$(find quadro)/description/leg_assets/lin_top_r.stl"/>
      </geometry>
      <material name="lin_top_r_material">
        <color rgba="1 0.756863 0.054902 1"/>
      </material>
    </visual>
    <collision>
      <origin xyz="-2.77556e-17 4.16334e-17 0.003" rpy="1.5708 -7.50078e-16 5.55112e-17"/>
      <geometry>
        <mesh filename="file://$(find quadro)/description/leg_assets/lin_top_r.stl"/>
      </geometry>
    </collision>
    <!-- Part bearing_2 -->
    <visual>
      <origin xyz="0 -0.05 -0.0255" rpy="-3.14159 -1.19417e-15 -5.55112e-17"/>
      <geometry>
        <mesh filename="file://$(find quadro)/description/leg_assets/bearing.stl"/>
      </geometry>
      <material name="bearing_2_material">
        <color rgba="0.615686 0.811765 0.929412 1"/>
      </material>
    </visual>
    <collision>
      <origin xyz="0 -0.05 -0.0255" rpy="-3.14159 -1.19417e-15 -5.55112e-17"/>
      <geometry>
        <mesh filename="file://$(find quadro)/description/leg_assets/bearing.stl"/>
      </geometry>
    </collision>
    <!-- Part shaft_3 -->
    <visual>
      <origin xyz="0 1.38778e-17 0.01" rpy="1.5708 1.5708 0"/>
      <geometry>
        <mesh filename="file://$(find quadro)/description/leg_assets/shaft.stl"/>
      </geometry>
      <material name="shaft_3_material">
        <color rgba="0.498039 0.498039 0.498039 1"/>
      </material>
    </visual>
    <collision>
      <origin xyz="0 1.38778e-17 0.01" rpy="1.5708 1.5708 0"/>
      <geometry>
        <mesh filename="file://$(find quadro)/description/leg_assets/shaft.stl"/>
      </geometry>
    </collision>
  </link>
  <!-- Joint from lin_2_br to lin_top_r -->
  <joint name="joint_br_3" type="revolute">
    <origin xyz="8.25728e-16 -8.32667e-17 -0.0485" rpy="-1.90199e-14 -3.69158e-14 0.436332"/>
    <parent link="lin_2_br"/>
    <child link="lin_top_r"/>
    <axis xyz="0 0 -1"/>
    <limit effort="10" velocity="10" lower="-3.141592653589793" upper="3.141592653589793"/>
  </joint>
  <!-- Link lin_4_r -->
  <link name="lin_4_r">
    <inertial>
      <origin xyz="-0.00037679 -0.0270176 -5.21118e-10" rpy="0 0 0"/>
      <mass value="0.0488058"/>
      <inertia ixx="0.000183398" ixy="1.69668e-06" ixz="2.68516e-13" iyy="4.65047e-06" iyz="1.73007e-12" izz="0.00018765"/>
    </inertial>
    <!-- Part lin_4_r -->
    <visual>
      <origin xyz="0.2 -7.88258e-15 -0.0085" rpy="-1.5708 -1.18604e-16 -3.9746e-14"/>
      <geometry>
        <mesh filename="file://$(find quadro)/description/leg_assets/lin_4_r.stl"/>
      </geometry>
      <material name="lin_4_r_material">
        <color rgba="1 0.756863 0.054902 1"/>
      </material>
    </visual>
    <collision>
      <origin xyz="0.2 -7.88258e-15 -0.0085" rpy="-1.5708 -1.18604e-16 -3.9746e-14"/>
      <geometry>
        <mesh filename="file://$(find quadro)/description/leg_assets/lin_4_r.stl"/>
      </geometry>
    </collision>
    <!-- Part bearing_3 -->
    <visual>
      <origin xyz="1.94289e-15 0.05 -1.38778e-17" rpy="3.14159 -1.18604e-16 -3.95795e-14"/>
      <geometry>
        <mesh filename="file://$(find quadro)/description/leg_assets/bearing.stl"/>
      </geometry>
      <material name="bearing_3_material">
        <color rgba="0.615686 0.811765 0.929412 1"/>
      </material>
    </visual>
    <collision>
      <origin xyz="1.94289e-15 0.05 -1.38778e-17" rpy="3.14159 -1.18604e-16 -3.95795e-14"/>
      <geometry>
        <mesh filename="file://$(find quadro)/description/leg_assets/bearing.stl"/>
      </geometry>
    </collision>
  </link>
  <!-- Joint from lin_2_br to lin_4_r -->
  <joint name="br_l4_l3" type="revolute">
    <origin xyz="-0.068404 -0.187939 -0.074" rpy="3.14159 -3.7582e-14 0.436332"/>
    <parent link="lin_2_br"/>
    <child link="lin_4_r"/>
    <axis xyz="0 0 -1"/>
    <limit effort="10" velocity="10" lower="-3.141592653589793" upper="3.141592653589793"/>
    <mimic joint="joint_br_3" multiplier="-1.0"/>
  </joint>
  <!-- Joint from shaft to lin_2_br -->
  <joint name="joint_br_2" type="revolute">
    <origin xyz="-0.0035 -0.00606218 -0.0735" rpy="1.5708 8.1119e-15 -0.523599"/>
    <parent link="shaft"/>
    <child link="lin_2_br"/>
    <axis xyz="0 0 -1"/>
    <limit effort="10" velocity="10" lower="-3.141592653589793" upper="3.141592653589793"/>
  </joint>
  <!-- Joint from motor to shaft -->
  <joint name="joint_br_1" type="revolute">
    <origin xyz="-0.055 0.0342754 0.061" rpy="-3.14159 -2.04333e-29 -1.5708"/>
    <parent link="motor"/>
    <child link="shaft"/>
    <axis xyz="0 0 -1"/>
    <limit effort="10" velocity="10" lower="-3.141592653589793" upper="3.141592653589793"/>
  </joint>
  <!-- Link shaft_2 -->
  <link name="shaft_2">
    <inertial>
      <origin xyz="-0.00365203 0.00743033 -0.0535667" rpy="0 0 0"/>
      <mass value="0.500834"/>
      <inertia ixx="0.000662397" ixy="-4.87254e-05" ixz="-1.77194e-05" iyy="0.000709837" iyz="3.40867e-05" izz="0.000280763"/>
    </inertial>
    <!-- Part shaft_4 -->
    <visual>
      <origin xyz="0 0 0.01" rpy="1.5708 1.5708 0"/>
      <geometry>
        <mesh filename="file://$(find quadro)/description/leg_assets/shaft.stl"/>
      </geometry>
      <material name="shaft_4_material">
        <color rgba="0.498039 0.498039 0.498039 1"/>
      </material>
    </visual>
    <collision>
      <origin xyz="0 0 0.01" rpy="1.5708 1.5708 0"/>
      <geometry>
        <mesh filename="file://$(find quadro)/description/leg_assets/shaft.stl"/>
      </geometry>
    </collision>
    <!-- Part motor_5 -->
    <visual>
      <origin xyz="-0.0085 0.0147224 -0.0735" rpy="1.5708 8.92383e-17 -1.0472"/>
      <geometry>
        <mesh filename="file://$(find quadro)/description/leg_assets/motor.stl"/>
      </geometry>
      <material name="motor_5_material">
        <color rgba="0.498039 0.498039 0.498039 1"/>
      </material>
    </visual>
    <collision>
      <origin xyz="-0.0085 0.0147224 -0.0735" rpy="1.5708 8.92383e-17 -1.0472"/>
      <geometry>
        <mesh filename="file://$(find quadro)/description/leg_assets/motor.stl"/>
      </geometry>
    </collision>
    <!-- Part lin_1_support_bl -->
    <visual>
      <origin xyz="-0.0485 0.0840045 -0.0735" rpy="-2.61799 -1.5708 0"/>
      <geometry>
        <mesh filename="file://$(find quadro)/description/leg_assets/lin_1_support_bl.stl"/>
      </geometry>
      <material name="lin_1_support_bl_material">
        <color rgba="1 0.756863 0.054902 1"/>
      </material>
    </visual>
    <collision>
      <origin xyz="-0.0485 0.0840045 -0.0735" rpy="-2.61799 -1.5708 0"/>
      <geometry>
        <mesh filename="file://$(find quadro)/description/leg_assets/lin_1_support_bl.stl"/>
      </geometry>
    </collision>
  </link>
  <!-- Link motor_2 -->
  <link name="motor_2">
    <inertial>
      <origin xyz="-0.00512367 0.0104232 -0.0435875" rpy="0 0 0"/>
      <mass value="0.551476"/>
      <inertia ixx="0.00130661" ixy="0.000304518" ixz="-9.96006e-05" iyy="0.000599134" iyz="0.000185395" izz="0.00132552"/>
    </inertial>
    <!-- Part lin_3_top_l -->
    <visual>
      <origin xyz="6.52256e-16 1.11022e-16 0.087" rpy="-1.5708 7.28298e-16 -1.22173"/>
      <geometry>
        <mesh filename="file://$(find quadro)/description/leg_assets/lin_3_top_l.stl"/>
      </geometry>
      <material name="lin_3_top_l_material">
        <color rgba="1 0.756863 0.054902 1"/>
      </material>
    </visual>
    <collision>
      <origin xyz="6.52256e-16 1.11022e-16 0.087" rpy="-1.5708 7.28298e-16 -1.22173"/>
      <geometry>
        <mesh filename="file://$(find quadro)/description/leg_assets/lin_3_top_l.stl"/>
      </geometry>
    </collision>
    <!-- Part lin_2_bl -->
    <visual>
      <origin xyz="-6.93889e-18 -5.55112e-17 -0.0195" rpy="1.5708 4.12056e-17 1.13446"/>
      <geometry>
        <mesh filename="file://$(find quadro)/description/leg_assets/lin_2_bl.stl"/>
      </geometry>
      <material name="lin_2_bl_material">
        <color rgba="1 0.756863 0.054902 1"/>
      </material>
    </visual>
    <collision>
      <origin xyz="-6.93889e-18 -5.55112e-17 -0.0195" rpy="1.5708 4.12056e-17 1.13446"/>
      <geometry>
        <mesh filename="file://$(find quadro)/description/leg_assets/lin_2_bl.stl"/>
      </geometry>
    </collision>
    <!-- Part lin_3_bot_l -->
    <visual>
      <origin xyz="6.80012e-16 5.55112e-17 0.087" rpy="-1.5708 -4.65192e-16 -1.22173"/>
      <geometry>
        <mesh filename="file://$(find quadro)/description/leg_assets/lin_3_bot_l.stl"/>
      </geometry>
      <material name="lin_3_bot_l_material">
        <color rgba="1 0.756863 0.054902 1"/>
      </material>
    </visual>
    <collision>
      <origin xyz="6.80012e-16 5.55112e-17 0.087" rpy="-1.5708 -4.65192e-16 -1.22173"/>
      <geometry>
        <mesh filename="file://$(find quadro)/description/leg_assets/lin_3_bot_l.stl"/>
      </geometry>
    </collision>
    <!-- Part shaft_5 -->
    <visual>
      <origin xyz="0 0 0.01" rpy="1.5708 1.5708 0"/>
      <geometry>
        <mesh filename="file://$(find quadro)/description/leg_assets/shaft.stl"/>
      </geometry>
      <material name="shaft_5_material">
        <color rgba="0.498039 0.498039 0.498039 1"/>
      </material>
    </visual>
    <collision>
      <origin xyz="0 0 0.01" rpy="1.5708 1.5708 0"/>
      <geometry>
        <mesh filename="file://$(find quadro)/description/leg_assets/shaft.stl"/>
      </geometry>
    </collision>
    <!-- Part motor_6 -->
    <visual>
      <origin xyz="8.95117e-16 2.77556e-17 -0.0385" rpy="-2.70526 1.5708 0"/>
      <geometry>
        <mesh filename="file://$(find quadro)/description/leg_assets/motor.stl"/>
      </geometry>
      <material name="motor_6_material">
        <color rgba="0.498039 0.498039 0.498039 1"/>
      </material>
    </visual>
    <collision>
      <origin xyz="8.95117e-16 2.77556e-17 -0.0385" rpy="-2.70526 1.5708 0"/>
      <geometry>
        <mesh filename="file://$(find quadro)/description/leg_assets/motor.stl"/>
      </geometry>
    </collision>
  </link>
  <!-- Link shaft_3 -->
  <link name="shaft_3">
    <inertial>
      <origin xyz="0.00329395 0.00299792 -0.0125923" rpy="0 0 0"/>
      <mass value="0.140118"/>
      <inertia ixx="3.12408e-05" ixy="-1.26751e-05" ixz="5.95745e-06" iyy="3.25345e-05" iyz="5.42205e-06" izz="4.62705e-05"/>
    </inertial>
    <!-- Part shaft_6 -->
    <visual>
      <origin xyz="8.67362e-18 2.77556e-17 0.01" rpy="1.5708 1.5708 0"/>
      <geometry>
        <mesh filename="file://$(find quadro)/description/leg_assets/shaft.stl"/>
      </geometry>
      <material name="shaft_6_material">
        <color rgba="0.498039 0.498039 0.498039 1"/>
      </material>
    </visual>
    <collision>
      <origin xyz="8.67362e-18 2.77556e-17 0.01" rpy="1.5708 1.5708 0"/>
      <geometry>
        <mesh filename="file://$(find quadro)/description/leg_assets/shaft.stl"/>
      </geometry>
    </collision>
    <!-- Part bearing_4 -->
    <visual>
      <origin xyz="0.0353553 0.0353553 -0.0255" rpy="3.14159 2.00877e-16 -0.785398"/>
      <geometry>
        <mesh filename="file://$(find quadro)/description/leg_assets/bearing.stl"/>
      </geometry>
      <material name="bearing_4_material">
        <color rgba="0.615686 0.811765 0.929412 1"/>
      </material>
    </visual>
    <collision>
      <origin xyz="0.0353553 0.0353553 -0.0255" rpy="3.14159 2.00877e-16 -0.785398"/>
      <geometry>
        <mesh filename="file://$(find quadro)/description/leg_assets/bearing.stl"/>
      </geometry>
    </collision>
    <!-- Part lin_top_l -->
    <visual>
      <origin xyz="-5.20417e-18 5.55112e-17 0.1545" rpy="-1.5708 1.45366e-16 -0.785398"/>
      <geometry>
        <mesh filename="file://$(find quadro)/description/leg_assets/lin_top_l.stl"/>
      </geometry>
      <material name="lin_top_l_material">
        <color rgba="1 0.756863 0.054902 1"/>
      </material>
    </visual>
    <collision>
      <origin xyz="-5.20417e-18 5.55112e-17 0.1545" rpy="-1.5708 1.45366e-16 -0.785398"/>
      <geometry>
        <mesh filename="file://$(find quadro)/description/leg_assets/lin_top_l.stl"/>
      </geometry>
    </collision>
  </link>
  <!-- Joint from motor_2 to shaft_3 -->
  <joint name="joint_bl_3" type="revolute">
    <origin xyz="9.22873e-16 8.32667e-17 -0.0485" rpy="8.67076e-16 -1.64245e-15 0.349066"/>
    <parent link="motor_2"/>
    <child link="shaft_3"/>
    <axis xyz="0 0 1"/>
    <limit effort="10" velocity="10" lower="-3.141592653589793" upper="3.141592653589793"/>
  </joint>
  <!-- Link lin_4_l -->
  <link name="lin_4_l">
    <inertial>
      <origin xyz="-0.000328446 -0.0235508 -0.0035" rpy="0 0 0"/>
      <mass value="0.0559903"/>
      <inertia ixx="0.000188216" ixy="1.63294e-06" ixz="2.67287e-13" iyy="4.89802e-06" iyz="1.6419e-12" izz="0.000192656"/>
    </inertial>
    <!-- Part bearing_5 -->
    <visual>
      <origin xyz="0 0.05 -0.0035" rpy="3.14159 1.9226e-17 5.55112e-17"/>
      <geometry>
        <mesh filename="file://$(find quadro)/description/leg_assets/bearing.stl"/>
      </geometry>
      <material name="bearing_5_material">
        <color rgba="0.615686 0.811765 0.929412 1"/>
      </material>
    </visual>
    <collision>
      <origin xyz="0 0.05 -0.0035" rpy="3.14159 1.9226e-17 5.55112e-17"/>
      <geometry>
        <mesh filename="file://$(find quadro)/description/leg_assets/bearing.stl"/>
      </geometry>
    </collision>
    <!-- Part bearing_6 -->
    <visual>
      <origin xyz="-5.55112e-17 0 -0.0035" rpy="3.14159 1.9226e-17 5.55112e-17"/>
      <geometry>
        <mesh filename="file://$(find quadro)/description/leg_assets/bearing.stl"/>
      </geometry>
      <material name="bearing_6_material">
        <color rgba="0.615686 0.811765 0.929412 1"/>
      </material>
    </visual>
    <collision>
      <origin xyz="-5.55112e-17 0 -0.0035" rpy="3.14159 1.9226e-17 5.55112e-17"/>
      <geometry>
        <mesh filename="file://$(find quadro)/description/leg_assets/bearing.stl"/>
      </geometry>
    </collision>
    <!-- Part lin_4_l -->
    <visual>
      <origin xyz="0.2 0 0.1565" rpy="-1.5708 1.9226e-17 0"/>
      <geometry>
        <mesh filename="file://$(find quadro)/description/leg_assets/lin_4_l.stl"/>
      </geometry>
      <material name="lin_4_l_material">
        <color rgba="1 0.756863 0.054902 1"/>
      </material>
    </visual>
    <collision>
      <origin xyz="0.2 0 0.1565" rpy="-1.5708 1.9226e-17 0"/>
      <geometry>
        <mesh filename="file://$(find quadro)/description/leg_assets/lin_4_l.stl"/>
      </geometry>
    </collision>
  </link>
  <!-- Joint from motor_2 to lin_4_l -->
  <joint name="bl_l4_l3" type="revolute">
    <origin xyz="-0.068404 0.187939 -0.0705" rpy="7.63706e-16 -1.37363e-15 -0.436332"/>
    <parent link="motor_2"/>
    <child link="lin_4_l"/>
    <axis xyz="0 0 1"/>
    <limit effort="10" velocity="10" lower="-3.141592653589793" upper="3.141592653589793"/>
    <mimic joint="joint_bl_3" multiplier="1.0"/>
  </joint>
  <!-- Joint from shaft_2 to motor_2 -->
  <joint name="joint_bl_2" type="revolute">
    <origin xyz="-0.0035 0.00606218 -0.0735" rpy="-1.5708 3.45644e-16 0.523599"/>
    <parent link="shaft_2"/>
    <child link="motor_2"/>
    <axis xyz="0 0 1"/>
    <limit effort="10" velocity="10" lower="-3.141592653589793" upper="3.141592653589793"/>
  </joint>
  <!-- Joint from motor to shaft_2 -->
  <joint name="joint_bl_1" type="revolute">
    <origin xyz="0.055 0.0342754 0.061" rpy="-3.14159 2.64698e-23 -1.5708"/>
    <parent link="motor"/>
    <child link="shaft_2"/>
    <axis xyz="0 0 -1"/>
    <limit effort="10" velocity="10" lower="-3.141592653589793" upper="3.141592653589793"/>
  </joint>
</robot>
