<?xml version="1.0" ?>
<!-- Generated using onshape-to-robot -->
<!-- Onshape https://cad.onshape.com/documents/ed1b080484db78e51ca91539/w/7397a458a49a8100160f52cd/e/9cc5d95f68bd237afce05dc0 -->
<robot name="robot" xmlns:xacro="http://www.ros.org/wiki/xacro">
<xacro:arg name="sim_mode" default="false"/>

<xacro:if value="$(arg sim_mode)">
  <xacro:include filename="$(find quadro)/description/robot.gazebo" />
</xacro:if>

<xacro:unless value="$(arg sim_mode)">
  <xacro:include filename="$(find quadro)/description/robot_ros2_control.xacro" />
</xacro:unless>
  <!-- Link motor -->
    <link name="world"/>

  <joint name="fixed" type="fixed">
    <parent link="world"/>
    <child link="motor"/>
  </joint>


  <link name="motor">
    <inertial>
      <origin xyz="0.00027739 0.000267795 0.0236674" rpy="0 0 0"/>
      <mass value="0.254057"/>
      <inertia ixx="0.000130963" ixy="2.48748e-08" ixz="1.56476e-08" iyy="0.000134228" iyz="-9.95815e-07" izz="0.0002245"/>
    </inertial>
    <!-- Part motor -->
    <visual>
      <origin xyz="-9.04138e-15 0.000467452 0.011" rpy="-1.5708 -1.5708 0"/>
      <geometry>
        <mesh filename="file://$(find quadro)/description/assets/motor.stl"/>
      </geometry>
      <material name="motor_material">
        <color rgba="0.498039 0.498039 0.498039 1"/>
      </material>
    </visual>
    <collision>
      <origin xyz="-9.04138e-15 0.000467452 0.011" rpy="-1.5708 -1.5708 0"/>
      <geometry>
        <mesh filename="file://$(find quadro)/description/assets/motor.stl"/>
      </geometry>
    </collision>
  </link>
  <!-- Link shaft -->
  <link name="shaft">
    <inertial>
      <origin xyz="3.38329e-17 3.80039e-17 -0.00969537" rpy="0 0 0"/>
      <mass value="0.113398"/>
      <inertia ixx="1.2016e-05" ixy="0" ixz="0" iyy="1.2016e-05" iyz="0" izz="1.68287e-05"/>
    </inertial>
    <!-- Part shaft -->
    <visual>
      <origin xyz="0 1.05626e-18 0.01" rpy="1.5708 1.5708 0"/>
      <geometry>
        <mesh filename="file://$(find quadro)/description/assets/shaft.stl"/>
      </geometry>
      <material name="shaft_material">
        <color rgba="0.498039 0.498039 0.498039 1"/>
      </material>
    </visual>
    <collision>
      <origin xyz="0 1.05626e-18 0.01" rpy="1.5708 1.5708 0"/>
      <geometry>
        <mesh filename="file://$(find quadro)/description/assets/shaft.stl"/>
      </geometry>
    </collision>
  </link>
  <!-- Link link -->
  <link name="link">
    <inertial>
      <origin xyz="0.15 -1.94567e-18 -0.015" rpy="0 0 0"/>
      <mass value="2.1195"/>
      <inertia ixx="0.000317925" ixy="0" ixz="0" iyy="0.0160552" iyz="0" izz="0.0160552"/>
    </inertial>
    <!-- Part link -->
    <visual>
      <origin xyz="0 -8.67362e-19 -0.015" rpy="3.14159 -0 0"/>
      <geometry>
        <mesh filename="file://$(find quadro)/description/assets/link.stl"/>
      </geometry>
      <material name="link_material">
        <color rgba="0.980392 0.713725 0.00392157 1"/>
      </material>
    </visual>
    <collision>
      <origin xyz="0 -8.67362e-19 -0.015" rpy="3.14159 -0 0"/>
      <geometry>
        <mesh filename="file://$(find quadro)/description/assets/link.stl"/>
      </geometry>
    </collision>
  </link>
  <!-- Joint from shaft to link -->
  <joint name="link_joint" type="fixed">
    <origin xyz="-3.79471e-19 1.05626e-18 -0.023" rpy="-1.05466e-16 -7.51113e-33 -1.5708"/>
    <parent link="shaft"/>
    <child link="link"/>
    <axis xyz="0 0 1"/>
    <limit effort="10" velocity="10"/>
  </joint>
  <!-- Joint from motor to shaft -->
  <joint name="shaft_joint" type="continuous">
    <origin xyz="-9.04138e-15 0.000467452 0.021" rpy="3.14159 -0 -1.5708"/>
    <parent link="motor"/>
    <child link="shaft"/>
    <axis xyz="0 0 1"/>
    <!-- <limit effort="10" velocity="10" lower="-3.141592653589793" upper="3.141592653589793"/> -->
  </joint>
</robot>
