<?xml version="1.0" ?>
<!-- =================================================================================== -->
<!-- |    This document was autogenerated by xacro from leg.xacro                      | -->
<!-- |    EDITING THIS FILE BY HAND IS NOT RECOMMENDED                                 | -->
<!-- =================================================================================== -->
<!-- Generated using onshape-to-robot -->
<!-- Onshape https://cad.onshape.com/documents/bab46d1a02d1cb675f27d5f3/w/8adfe612a59991dc5461d3ee/e/fd595c6fbcbfabdca437c483 -->
<robot name="leg">
  <ros2_control name="GazeboSystem" type="system">
    <hardware>
      <plugin>gz_ros2_control/GazeboSimSystem</plugin>
    </hardware>
    <joint name="bl_m1_s1">
      <command_interface name="effort"/>
      <state_interface name="position"/>
      <state_interface name="velocity"/>
      <state_interface name="effort"/>
    </joint>
    <joint name="bl_m2_s2">
      <command_interface name="effort"/>
      <state_interface name="position"/>
      <state_interface name="velocity"/>
      <state_interface name="effort"/>
    </joint>
    <joint name="bl_l4_l3">
      <command_interface name="effort"/>
      <state_interface name="position"/>
      <state_interface name="velocity"/>
      <state_interface name="effort"/>
    </joint>
  </ros2_control>
  <gazebo>
    <plugin filename="gz_ros2_control-system" name="gz_ros2_control::GazeboSimROS2ControlPlugin">
      <parameters>/home/rooteq/ros2_ws/install/quadro/share/quadro/config/effort_controller.yaml</parameters>
    </plugin>
  </gazebo>
  <!-- <gazebo reference="lin_4_l">
    <mu1>1.0</mu1>
    <mu2>1.0</mu2>
    <minDepth>0.01</minDepth>
    <maxVel>10</maxVel>
    <kp>1e+10</kp>
    <kd>1.0</kd>
    <maxContacts>10</maxContacts>
  </gazebo>

  <gazebo reference="lin_4_l_2">
    <mu1>1.0</mu1>
    <mu2>1.0</mu2>
    <minDepth>0.01</minDepth>
    <maxVel>10</maxVel>
    <kp>1e+10</kp>
    <kd>1.0</kd>
    <maxContacts>10</maxContacts>
  </gazebo>

  <gazebo reference="lin_4_r">
    <mu1>1.0</mu1>
    <mu2>1.0</mu2>
    <minDepth>0.01</minDepth>
    <maxVel>10</maxVel>
    <kp>1e+10</kp>
    <kd>1.0</kd>
    <maxContacts>10</maxContacts>
  </gazebo>

  <gazebo reference="lin_4_r_2">
    <mu1>1.0</mu1>
    <mu2>1.0</mu2>
    <minDepth>0.01</minDepth>
    <maxVel>10</maxVel>
    <kp>1e+10</kp>
    <kd>1.0</kd>
    <maxContacts>10</maxContacts>
  </gazebo> -->
  <!-- <gazebo reference="motor">
    <material>${body_color}</material>
    <self_collide>true</self_collide>
    <gravity>true</gravity>
  </gazebo>

  <gazebo reference="shaft">
    <material>${body_color}</material>
    <self_collide>true</self_collide>
  </gazebo>

  <gazebo reference="joint_br_1">
    <preserveFixedJoint>true</preserveFixedJoint>
  </gazebo>

  <gazebo reference="joint_br_2">
    <preserveFixedJoint>true</preserveFixedJoint>
  </gazebo>
  <gazebo reference="joint_br_3">
    <preserveFixedJoint>true</preserveFixedJoint>
  </gazebo> -->
  <link name="world"/>
  <joint name="fixed" type="fixed">
    <parent link="world"/>
    <child link="motor"/>
  </joint>
  <!-- Link shaft -->
  <link name="shaft">
    <inertial>
      <origin rpy="0 0 0" xyz="-0.00100224 0.00617513 0.0818763"/>
      <mass value="0.453012"/>
      <inertia ixx="0.000489604" ixy="-7.28122e-06" ixz="1.56037e-06" iyy="0.000609097" iyz="-1.64399e-05" izz="0.000239462"/>
    </inertial>
    <!-- Part shaft -->
    <visual>
      <origin rpy="0.872665 -1.5708 0" xyz="-8.07509e-16 -4.69306e-16 0.011"/>
      <geometry>
        <mesh filename="file:///home/rooteq/ros2_ws/install/quadro/share/quadro/description/leg_assets/shaft.stl"/>
      </geometry>
      <material name="shaft_material">
        <color rgba="0.498039 0.498039 0.498039 1"/>
      </material>
    </visual>
    <collision>
      <origin rpy="0.872665 -1.5708 0" xyz="-8.07509e-16 -4.69306e-16 0.011"/>
      <geometry>
        <mesh filename="file:///home/rooteq/ros2_ws/install/quadro/share/quadro/description/leg_assets/shaft.stl"/>
      </geometry>
    </collision>
    <!-- Part motor -->
    <visual>
      <origin rpy="-1.5708 8.89644e-15 -1.48353" xyz="-0.00148165 0.0169353 0.0945"/>
      <geometry>
        <mesh filename="file:///home/rooteq/ros2_ws/install/quadro/share/quadro/description/leg_assets/motor.stl"/>
      </geometry>
      <material name="motor_material">
        <color rgba="0.498039 0.498039 0.498039 1"/>
      </material>
    </visual>
    <collision>
      <origin rpy="-1.5708 8.89644e-15 -1.48353" xyz="-0.00148165 0.0169353 0.0945"/>
      <geometry>
        <mesh filename="file:///home/rooteq/ros2_ws/install/quadro/share/quadro/description/leg_assets/motor.stl"/>
      </geometry>
    </collision>
    <!-- Part lin_1_support_bl -->
    <visual>
      <origin rpy="3.05433 1.5708 0" xyz="-0.00845411 0.0966309 0.0945"/>
      <geometry>
        <mesh filename="file:///home/rooteq/ros2_ws/install/quadro/share/quadro/description/leg_assets/lin_1_support_bl.stl"/>
      </geometry>
      <material name="lin_1_support_bl_material">
        <color rgba="0.901961 0.901961 0.901961 1"/>
      </material>
    </visual>
    <collision>
      <origin rpy="3.05433 1.5708 0" xyz="-0.00845411 0.0966309 0.0945"/>
      <geometry>
        <mesh filename="file:///home/rooteq/ros2_ws/install/quadro/share/quadro/description/leg_assets/lin_1_support_bl.stl"/>
      </geometry>
    </collision>
  </link>
  <!-- Link motor -->
  <link name="motor">
    <inertial>
      <origin rpy="0 0 0" xyz="-0.00034083 -2.5357e-05 0.00266737"/>
      <mass value="0.319783"/>
      <inertia ixx="0.00016651" ixy="-2.01865e-06" ixz="-8.2078e-07" iyy="0.000167286" iyz="9.47527e-07" izz="0.000282579"/>
    </inertial>
    <!-- Part motor_2 -->
    <visual>
      <origin rpy="2.26893 -1.5708 0" xyz="-6.78949e-19 8.0914e-19 -0.01"/>
      <geometry>
        <mesh filename="file:///home/rooteq/ros2_ws/install/quadro/share/quadro/description/leg_assets/motor.stl"/>
      </geometry>
      <material name="motor_2_material">
        <color rgba="0.498039 0.498039 0.498039 1"/>
      </material>
    </visual>
    <collision>
      <origin rpy="2.26893 -1.5708 0" xyz="-6.78949e-19 8.0914e-19 -0.01"/>
      <geometry>
        <mesh filename="file:///home/rooteq/ros2_ws/install/quadro/share/quadro/description/leg_assets/motor.stl"/>
      </geometry>
    </collision>
  </link>
  <!-- Joint from motor to shaft -->
  <joint name="bl_m1_s1" type="revolute">
    <origin rpy="4.96925e-15 -7.80392e-15 2.44346" xyz="-7.16465e-16 -4.82211e-16 -0.025"/>
    <parent link="motor"/>
    <child link="shaft"/>
    <axis xyz="0 0 1"/>
    <limit effort="10" lower="-3.14" upper="3.14" velocity="12"/>
    <joint_properties friction="0.5"/>
  </joint>
  <!-- Link shaft_2 -->
  <link name="shaft_2">
    <inertial>
      <origin rpy="0 0 0" xyz="0.00679431 0.00633758 -0.0491985"/>
      <mass value="0.524841"/>
      <inertia ixx="0.000610231" ixy="-0.000236595" ixz="0.000101861" iyy="0.000743295" iyz="0.00010283" izz="0.000885096"/>
    </inertial>
    <!-- Part lin_2_bl -->
    <visual>
      <origin rpy="1.5708 -9.2554e-16 -0.174533" xyz="-1.38778e-17 6.93889e-18 -0.0195"/>
      <geometry>
        <mesh filename="file:///home/rooteq/ros2_ws/install/quadro/share/quadro/description/leg_assets/lin_2_bl.stl"/>
      </geometry>
      <material name="lin_2_bl_material">
        <color rgba="0.901961 0.901961 0.901961 1"/>
      </material>
    </visual>
    <collision>
      <origin rpy="1.5708 -9.2554e-16 -0.174533" xyz="-1.38778e-17 6.93889e-18 -0.0195"/>
      <geometry>
        <mesh filename="file:///home/rooteq/ros2_ws/install/quadro/share/quadro/description/leg_assets/lin_2_bl.stl"/>
      </geometry>
    </collision>
    <!-- Part top_l -->
    <visual>
      <origin rpy="1.5708 -1.18469e-15 0.610865" xyz="2.77556e-17 -3.46945e-17 -0.0725"/>
      <geometry>
        <mesh filename="file:///home/rooteq/ros2_ws/install/quadro/share/quadro/description/leg_assets/top_l.stl"/>
      </geometry>
      <material name="top_l_material">
        <color rgba="0.901961 0.901961 0.901961 1"/>
      </material>
    </visual>
    <collision>
      <origin rpy="1.5708 -1.18469e-15 0.610865" xyz="2.77556e-17 -3.46945e-17 -0.0725"/>
      <geometry>
        <mesh filename="file:///home/rooteq/ros2_ws/install/quadro/share/quadro/description/leg_assets/top_l.stl"/>
      </geometry>
    </collision>
    <!-- Part motor_3 -->
    <visual>
      <origin rpy="-1.39626 1.5708 0" xyz="0 -1.38778e-17 -0.0395"/>
      <geometry>
        <mesh filename="file:///home/rooteq/ros2_ws/install/quadro/share/quadro/description/leg_assets/motor.stl"/>
      </geometry>
      <material name="motor_3_material">
        <color rgba="0.498039 0.498039 0.498039 1"/>
      </material>
    </visual>
    <collision>
      <origin rpy="-1.39626 1.5708 0" xyz="0 -1.38778e-17 -0.0395"/>
      <geometry>
        <mesh filename="file:///home/rooteq/ros2_ws/install/quadro/share/quadro/description/leg_assets/motor.stl"/>
      </geometry>
    </collision>
    <!-- Part bot_l -->
    <visual>
      <origin rpy="1.5708 -1.18469e-15 0.610865" xyz="4.16334e-17 -2.77556e-17 -0.0725"/>
      <geometry>
        <mesh filename="file:///home/rooteq/ros2_ws/install/quadro/share/quadro/description/leg_assets/bot_l.stl"/>
      </geometry>
      <material name="bot_l_material">
        <color rgba="0.901961 0.901961 0.901961 1"/>
      </material>
    </visual>
    <collision>
      <origin rpy="1.5708 -1.18469e-15 0.610865" xyz="4.16334e-17 -2.77556e-17 -0.0725"/>
      <geometry>
        <mesh filename="file:///home/rooteq/ros2_ws/install/quadro/share/quadro/description/leg_assets/bot_l.stl"/>
      </geometry>
    </collision>
    <!-- Part shaft_2 -->
    <visual>
      <origin rpy="1.5708 1.5708 0" xyz="-1.38778e-17 0 0.01"/>
      <geometry>
        <mesh filename="file:///home/rooteq/ros2_ws/install/quadro/share/quadro/description/leg_assets/shaft.stl"/>
      </geometry>
      <material name="shaft_2_material">
        <color rgba="0.498039 0.498039 0.498039 1"/>
      </material>
    </visual>
    <collision>
      <origin rpy="1.5708 1.5708 0" xyz="-1.38778e-17 0 0.01"/>
      <geometry>
        <mesh filename="file:///home/rooteq/ros2_ws/install/quadro/share/quadro/description/leg_assets/shaft.stl"/>
      </geometry>
    </collision>
  </link>
  <!-- Link shaft_3 -->
  <link name="shaft_3">
    <inertial>
      <origin rpy="0 0 0" xyz="-0.00823991 0.00823991 -0.0152617"/>
      <mass value="0.0992632"/>
      <inertia ixx="3.95043e-05" ixy="2.3154e-05" ixz="-1.04189e-05" iyy="3.95043e-05" iyz="1.04189e-05" izz="6.07656e-05"/>
    </inertial>
    <!-- Part bearing -->
    <visual>
      <origin rpy="-1.5708 -7.72957e-17 -2.35619" xyz="-0.0388909 0.0388909 -0.032"/>
      <geometry>
        <mesh filename="file:///home/rooteq/ros2_ws/install/quadro/share/quadro/description/leg_assets/bearing.stl"/>
      </geometry>
      <material name="bearing_material">
        <color rgba="0.439216 0.47451 0.501961 1"/>
      </material>
    </visual>
    <collision>
      <origin rpy="-1.5708 -7.72957e-17 -2.35619" xyz="-0.0388909 0.0388909 -0.032"/>
      <geometry>
        <mesh filename="file:///home/rooteq/ros2_ws/install/quadro/share/quadro/description/leg_assets/bearing.stl"/>
      </geometry>
    </collision>
    <!-- Part shaft_3 -->
    <visual>
      <origin rpy="1.5708 1.5708 0" xyz="1.38778e-17 -3.46945e-18 0.01"/>
      <geometry>
        <mesh filename="file:///home/rooteq/ros2_ws/install/quadro/share/quadro/description/leg_assets/shaft.stl"/>
      </geometry>
      <material name="shaft_3_material">
        <color rgba="0.498039 0.498039 0.498039 1"/>
      </material>
    </visual>
    <collision>
      <origin rpy="1.5708 1.5708 0" xyz="1.38778e-17 -3.46945e-18 0.01"/>
      <geometry>
        <mesh filename="file:///home/rooteq/ros2_ws/install/quadro/share/quadro/description/leg_assets/shaft.stl"/>
      </geometry>
    </collision>
    <!-- Part mid_l -->
    <visual>
      <origin rpy="1.5708 -7.72957e-17 -2.35619" xyz="1.38778e-17 0 -0.014"/>
      <geometry>
        <mesh filename="file:///home/rooteq/ros2_ws/install/quadro/share/quadro/description/leg_assets/mid_l.stl"/>
      </geometry>
      <material name="mid_l_material">
        <color rgba="0.901961 0.901961 0.901961 1"/>
      </material>
    </visual>
    <collision>
      <origin rpy="1.5708 -7.72957e-17 -2.35619" xyz="1.38778e-17 0 -0.014"/>
      <geometry>
        <mesh filename="file:///home/rooteq/ros2_ws/install/quadro/share/quadro/description/leg_assets/mid_l.stl"/>
      </geometry>
    </collision>
  </link>
  <!-- Joint from shaft_2 to shaft_3 -->
  <joint name="bl_m3_s3" type="revolute">
    <origin rpy="1.50009e-15 8.62308e-16 -2.3911" xyz="0 -2.77556e-17 -0.0495"/>
    <parent link="shaft_2"/>
    <child link="shaft_3"/>
    <axis xyz="0 0 1"/>
    <limit effort="10" lower="-3.14" upper="3.14" velocity="12"/>
    <joint_properties friction="0.5"/>
    <mimic joint="bl_l4_l3" multiplier="1.0"/>
  </joint>
  <!-- Link l4_l -->
  <link name="l4_l">
    <inertial>
      <origin rpy="0 0 0" xyz="0.000904018 0.036899 -0.00535524"/>
      <mass value="0.0940232"/>
      <inertia ixx="0.000523053" ixy="1.96238e-06" ixz="4.23975e-07" iyy="8.81622e-06" iyz="3.90493e-06" izz="0.000528442"/>
    </inertial>
    <!-- Part bearing_2 -->
    <visual>
      <origin rpy="-1.5708 -8.83135e-18 0" xyz="-2.77556e-17 8.32667e-17 -0.008"/>
      <geometry>
        <mesh filename="file:///home/rooteq/ros2_ws/install/quadro/share/quadro/description/leg_assets/bearing.stl"/>
      </geometry>
      <material name="bearing_2_material">
        <color rgba="0.439216 0.47451 0.501961 1"/>
      </material>
    </visual>
    <collision>
      <origin rpy="-1.5708 -8.83135e-18 0" xyz="-2.77556e-17 8.32667e-17 -0.008"/>
      <geometry>
        <mesh filename="file:///home/rooteq/ros2_ws/install/quadro/share/quadro/description/leg_assets/bearing.stl"/>
      </geometry>
    </collision>
    <!-- Part bearing_3 -->
    <visual>
      <origin rpy="-1.5708 -8.83135e-18 0" xyz="-5.55112e-17 -0.055 -0.008"/>
      <geometry>
        <mesh filename="file:///home/rooteq/ros2_ws/install/quadro/share/quadro/description/leg_assets/bearing.stl"/>
      </geometry>
      <material name="bearing_3_material">
        <color rgba="0.439216 0.47451 0.501961 1"/>
      </material>
    </visual>
    <collision>
      <origin rpy="-1.5708 -8.83135e-18 0" xyz="-5.55112e-17 -0.055 -0.008"/>
      <geometry>
        <mesh filename="file:///home/rooteq/ros2_ws/install/quadro/share/quadro/description/leg_assets/bearing.stl"/>
      </geometry>
    </collision>
    <!-- Part feet -->
    <visual>
      <origin rpy="-1.5708 3.00265e-16 -3.14159" xyz="-0.200014 -0.04 -0.039"/>
      <geometry>
        <mesh filename="file:///home/rooteq/ros2_ws/install/quadro/share/quadro/description/leg_assets/feet.stl"/>
      </geometry>
      <material name="feet_material">
        <color rgba="0.917647 0.917647 0.917647 1"/>
      </material>
    </visual>
    <collision>
      <origin rpy="-1.5708 3.00265e-16 -3.14159" xyz="-0.200014 -0.04 -0.039"/>
      <geometry>
        <mesh filename="file:///home/rooteq/ros2_ws/install/quadro/share/quadro/description/leg_assets/feet.stl"/>
      </geometry>
    </collision>
    <!-- Part l4_l -->
    <visual>
      <origin rpy="1.5708 -8.83135e-18 0" xyz="-0.16 -0.002 -0.008"/>
      <geometry>
        <mesh filename="file:///home/rooteq/ros2_ws/install/quadro/share/quadro/description/leg_assets/l4_l.stl"/>
      </geometry>
      <material name="l4_l_material">
        <color rgba="0.901961 0.901961 0.901961 1"/>
      </material>
    </visual>
    <collision>
      <origin rpy="1.5708 -8.83135e-18 0" xyz="-0.16 -0.002 -0.008"/>
      <geometry>
        <mesh filename="file:///home/rooteq/ros2_ws/install/quadro/share/quadro/description/leg_assets/l4_l.stl"/>
      </geometry>
    </collision>
  </link>
  <!-- Joint from shaft_2 to l4_l -->
  <joint name="bl_l4_l3" type="revolute">
    <origin rpy="-1.39777e-15 4.10207e-16 1.53589" xyz="0.129917 0.0934105 -0.0735"/>
    <parent link="shaft_2"/>
    <child link="l4_l"/>
    <axis xyz="0 0 1"/>
    <limit effort="10" lower="-3.14" upper="3.14" velocity="12"/>
    <joint_properties friction="0.5"/>
  </joint>
  <!-- Joint from shaft to shaft_2 -->
  <joint name="bl_m2_s2" type="revolute">
    <origin rpy="1.5708 -1.0472 -3.05433" xyz="-0.00061009 0.00697336 0.0945"/>
    <parent link="shaft"/>
    <child link="shaft_2"/>
    <axis xyz="0 0 1"/>
    <limit effort="10" lower="-3.14" upper="3.14" velocity="12"/>
    <joint_properties friction="0.5"/>
  </joint>
</robot>
